<?xml version="0.0" ?>
<!--
  ~ Copyright 2020 Google LLC
  ~
  ~ Licensed under the Apache License, Version 2.0 (the "License");
  ~ you may not use this file except in compliance with the License.
  ~ You may obtain a copy of the License at
  ~
  ~     https://www.apache.org/licenses/LICENSE-2.0
  ~
  ~ Unless required by applicable law or agreed to in writing, software
  ~ distributed under the License is distributed on an "AS IS" BASIS,
  ~ WITHOUT WARRANTIES OR CONDITIONS OF ANY KIND, either express or implied.
  ~ See the License for the specific language governing permissions and
  ~ limitations under the License.
  -->

<robot name="handle">
    <link name="root">
        <origin xyz="0 0 0"/>
        <inertial>
            <origin rpy="0 0 0" xyz="0.0 0.0 0.0"/>
            <mass value="10.0"/>
            <inertia ixx="1" ixy="0" ixz="0" iyy="1" iyz="0" izz="1"/>
        </inertial>
    </link>
    <link name="handleBody">
        <inertial>
            <origin rpy="0 0 0" xyz="0.0 0.0 0.1"/>
            <mass value="1.0"/>
            <inertia ixx="1" ixy="0" ixz="0" iyy="1" iyz="0" izz="1"/>
        </inertial>
        <visual>
            <origin rpy="0 0 0" xyz="0.0 0.0 0.0"/>
            <geometry>
                <mesh filename="handle.obj" scale="1 1 1"/>
            </geometry>
        </visual>
        <collision>
            <origin rpy="0 0 0" xyz="0.0 0.0 0.0"/>
            <geometry>
                <mesh filename="handle.obj" scale="1 1 1"/>
            </geometry>
        </collision>
    </link>
    <joint name="root" type="continuous">
        <parent link="root"/>
        <child link="handleBody"/>
        <origin rpy="0 0 0" xyz="0. 0.0 0.0"/>
        <axis xyz="0 -1 0"/>
    </joint>
</robot>

